Workbook

Sheet Cover
A1: plot # | B1: irrigation type | C1: soil | D1: jute | E1: Inoc | F1: Bare_1 | G1: Rock_1 | H1: Cyano_1 | I1: Lichen_1 | J1: Moss_1 | K1: %Bare_1 | L1: % cyano_1 | M1: %lichen | N1: %moss | O1: %LS_1 | P1: %TotalBiocrust_1 | S1: Bare_2 | T1: Rock_2 | U1: Cyano_2 | V1: Lichen_2 | W1: Bare fabric_2 | X1: Moss_2 | Y1: %Bare_2 | Z1: % cyano_2 | AA1: %lichen_2 | AB1: %moss_2 | AC1: %LS_2 | AD1: %TotalBiocrust_2 | AG1: Jute_2 | AH1: Plant_2 | AI1: % plant | AJ1: Average of LBug_g | AK1: Average of TBug_g | AL1: Average of Gug_g | AM1: tot chl a (665+750) | AN1: Row Labels | AO1: Average of LBmg_L | AP1: Average of TBmg_L | AQ1: Average of LBug | AR1: Average of LBug_g | AS1: Average of TBug_g | AT1: Average of Gug | AU1: Average of Gug_g | AV1: Average of Gmg_L | AW1: Average of TBug
A2: 1 | B2: Hoop | C2: native | D2: no | E2: C | F2: 20 | G2: 5 | K2: =F2*4 -> 80 | L2: =H2*4 -> 0 | M2: =I2*4 -> 0 | N2: =J2*4 -> 0 | O2: =M2+N2 -> 0 | P2: =SUM(L2:N2) -> 0 | S2: 20 | T2: 5 | U2: 0 | V2: 0 | W2: 0 | X2: 0 | Y2: 80 | Z2: 0 | AA2: 0 | AB2: 0 | AC2: 0 | AD2: =SUM(Z2:AB2) -> 0 | AH2: 0 | AI2: 0 | AM2: 12.478133
A3: 2 | B3: Hoop | C3: sand | D3: no | E3: B | F3: 22 | G3: 2 | I3: 1 | J3: 0.5 | K3: =F3*4 -> 88 | L3: =H3*4 -> 0 | M3: =I3*4 -> 4 | N3: =J3*4 -> 2 | O3: =M3+N3 -> 6 | P3: =SUM(L3:N3) -> 6 | S3: 14 | T3: 8 | U3: 0.5 | V3: 3 | W3: 0 | X3: 0.5 | Y3: 56 | Z3: 2 | AA3: 12 | AB3: 2 | AC3: 14 | AD3: =SUM(Z3:AB3) -> 16 | AH3: 0 | AI3: 38 | AM3: 18.549205
A4: 3 | B4: Hoop | C4: native | D4: J_scrape | E4: B | F4: 18 | G4: 5 | I4: 2 | J4: 0.5 | K4: =F4*4 -> 72 | L4: =H4*4 -> 0 | M4: =I4*4 -> 8 | N4: =J4*4 -> 2 | O4: =M4+N4 -> 10 | P4: =SUM(L4:N4) -> 10 | S4: 9 | T4: 7 | U4: 1 | V4: 3 | W4: 0 | X4: 0.5 | Y4: 36 | Z4: 4 | AA4: 12 | AB4: 2 | AC4: 14 | AD4: =SUM(Z4:AB4) -> 18 | AH4: 0 | AI4: 80 | AM4: 51.539722
A5: 4 | B5: Hoop | C5: native | D5: J_direct | E5: B | F5: 16 | G5: 6 | I5: 1 | J5: 2 | K5: =F5*4 -> 64 | L5: =H5*4 -> 0 | M5: =I5*4 -> 4 | N5: =J5*4 -> 8 | O5: =M5+N5 -> 12 | P5: =SUM(L5:N5) -> 12 | S5: 11 | T5: 5 | U5: 6 | V5: 3 | W5: 0 | X5: 0.5 | Y5: 44 | Z5: 24 | AA5: 12 | AB5: 2 | AC5: 14 | AD5: =SUM(Z5:AB5) -> 38 | AH5: 0 | AI5: 64.5 | AJ5: 158.41232 | AK5: 257.73295 | AL5: 306.96719 | AM5: 37.01237 | AN5: 4 | AO5: 6.304549 | AP5: 20.339783 | AQ5: 32.62281 | AR5: 158.41232 | AS5: 257.73295 | AT5: 63.54645 | AU5: 306.96719 | AV5: 10.9336 | AW5: 53.317
A6: 5 | B6: Hoop | C6: sand | D6: J_direct | E6: B | F6: 17 | G6: 6 | I6: 2 | J6: 0.5 | K6: =F6*4 -> 68 | L6: =H6*4 -> 0 | M6: =I6*4 -> 8 | N6: =J6*4 -> 2 | O6: =M6+N6 -> 10 | P6: =SUM(L6:N6) -> 10 | S6: 10 | T6: 4 | U6: 9 | V6: 2 | W6: 0 | X6: 0.5 | Y6: 40 | Z6: 36 | AA6: 8 | AB6: 2 | AC6: 10 | AD6: =SUM(Z6:AB6) -> 46 | AH6: 0 | AI6: 30.5 | AM6: 37.703234
A7: 6 | B7: Hoop | C7: native | D7: J_direct | E7: C | F7: 17 | G7: 8 | K7: =F7*4 -> 68 | L7: =H7*4 -> 0 | M7: =I7*4 -> 0 | N7: =J7*4 -> 0 | O7: =M7+N7 -> 0 | P7: =SUM(L7:N7) -> 0 | S7: 12 | T7: 6 | U7: 1 | V7: 0 | W7: 0 | X7: 0 | Y7: 48 | Z7: 4 | AA7: 0 | AB7: 0 | AC7: 0 | AD7: =SUM(Z7:AB7) -> 4 | AH7: 6 | AI7: 25 | AM7: 7.2302423
A8: 7 | B8: Hoop | C8: sand | D8: J_scrape | E8: B | F8: 19 | G8: 3 | I8: 3 | J8: 0.5 | K8: =F8*4 -> 76 | L8: =H8*4 -> 0 | M8: =I8*4 -> 12 | N8: =J8*4 -> 2 | O8: =M8+N8 -> 14 | P8: =SUM(L8:N8) -> 14 | S8: 12 | T8: 2 | U8: 7 | V8: 3 | W8: 0 | X8: 0.5 | Y8: 48 | Z8: 28 | AA8: 12 | AB8: 2 | AC8: 14 | AD8: =SUM(Z8:AB8) -> 42 | AH8: 1 | AI8: 19 | AM8: 26.856773
A9: 8 | B9: Hoop | C9: sand | D9: no | E9: B | F9: 20 | G9: 2 | I9: 3 | K9: =F9*4 -> 80 | L9: =H9*4 -> 0 | M9: =I9*4 -> 12 | N9: =J9*4 -> 0 | O9: =M9+N9 -> 12 | P9: =SUM(L9:N9) -> 12 | S9: 13 | T9: 3 | U9: 7 | V9: 1 | W9: 1 | X9: 0.5 | Y9: 52 | Z9: 28 | AA9: 4 | AB9: 2 | AC9: 6 | AD9: =SUM(Z9:AB9) -> 34 | AH9: 0 | AI9: 23.5 | AM9: 15.51395
A10: 9 | B10: Hoop | C10: sand | D10: no | E10: B | F10: 19 | G10: 4 | I10: 2 | J10: 0.5 | K10: =F10*4 -> 76 | L10: =H10*4 -> 0 | M10: =I10*4 -> 8 | N10: =J10*4 -> 2 | O10: =M10+N10 -> 10 | P10: =SUM(L10:N10) -> 10 | S10: 12 | T10: 2 | U10: 5 | V10: 1 | W10: 4 | X10: 1 | Y10: 48 | Z10: 20 | AA10: 4 | AB10: 4 | AC10: 8 | AD10: =SUM(Z10:AB10) -> 28 | AH10: 0 | AI10: 22.5 | AM10: 22.760237
A11: 10 | B11: Hoop | C11: native | D11: no | E11: B | F11: 21 | G11: 2 | I11: 2 | J11: 0.5 | K11: =F11*4 -> 84 | L11: =H11*4 -> 0 | M11: =I11*4 -> 8 | N11: =J11*4 -> 2 | O11: =M11+N11 -> 10 | P11: =SUM(L11:N11) -> 10 | S11: 1 | T11: 3 | U11: 8 | V11: 4 | W11: 9 | X11: 0.5 | Y11: 4 | Z11: 32 | AA11: 16 | AB11: 2 | AC11: 18 | AD11: =SUM(Z11:AB11) -> 50 | AH11: 0 | AI11: 39 | AM11: 21.99933
A12: 11 | B12: Hoop | C12: sand | D12: J_scrape | E12: C | F12: 22 | G12: 3 | K12: =F12*4 -> 88 | L12: =H12*4 -> 0 | M12: =I12*4 -> 0 | N12: =J12*4 -> 0 | O12: =M12+N12 -> 0 | P12: =SUM(L12:N12) -> 0 | S12: 18 | T12: 1 | U12: 0 | V12: 0 | W12: 0 | X12: 0 | Y12: 72 | Z12: 0 | AA12: 0 | AB12: 0 | AC12: 0 | AD12: =SUM(Z12:AB12) -> 0 | AH12: 6 | AI12: 0 | AM12: 7.4506156
A13: 12 | B13: Hoop | C13: sand | D13: no | E13: C | F13: 24 | G13: 1 | K13: =F13*4 -> 96 | L13: =H13*4 -> 0 | M13: =I13*4 -> 0 | N13: =J13*4 -> 0 | O13: =M13+N13 -> 0 | P13: =SUM(L13:N13) -> 0 | S13: 24 | T13: 1 | U13: 0 | V13: 0 | W13: 0.5 | X13: 0 | Y13: 96 | Z13: 0 | AA13: 0 | AB13: 0 | AC13: 0 | AD13: =SUM(Z13:AB13) -> 0 | AH13: 0 | AI13: 0 | AM13: 1.7377691
A14: 13 | B14: Hoop | C14: sand | D14: J_direct | E14: B | F14: 21 | G14: 2 | I14: 2 | K14: =F14*4 -> 84 | L14: =H14*4 -> 0 | M14: =I14*4 -> 8 | N14: =J14*4 -> 0 | O14: =M14+N14 -> 8 | P14: =SUM(L14:N14) -> 8 | S14: 7 | T14: 1 | U14: 9 | V14: 5 | W14: 0 | X14: 1 | Y14: 28 | Z14: 36 | AA14: 20 | AB14: 4 | AC14: 24 | AD14: =SUM(Z14:AB14) -> 60 | AH14: 2 | AI14: 12 | AM14: 34.183097
A15: 14 | B15: Hoop | C15: native | D15: J_scrape | E15: B | F15: 20 | G15: 2 | I15: 3 | J15: 0.5 | K15: =F15*4 -> 80 | L15: =H15*4 -> 0 | M15: =I15*4 -> 12 | N15: =J15*4 -> 2 | O15: =M15+N15 -> 14 | P15: =SUM(L15:N15) -> 14 | S15: 11 | T15: 5 | U15: 3 | V15: 4 | W15: 0 | X15: 0.5 | Y15: 44 | Z15: 12 | AA15: 16 | AB15: 2 | AC15: 18 | AD15: =SUM(Z15:AB15) -> 30 | AH15: 2 | AI15: 12.5 | AM15: 19.504033
A16: 15 | B16: Hoop | C16: sand | D16: J_scrape | E16: B | F16: 24 | G16: 1 | I16: 0.5 | J16: 0.5 | K16: =F16*4 -> 96 | L16: =H16*4 -> 0 | M16: =I16*4 -> 2 | N16: =J16*4 -> 2 | O16: =M16+N16 -> 4 | P16: =SUM(L16:N16) -> 4 | S16: 7 | T16: 1 | U16: 14 | V16: 1 | W16: 0 | X16: 1 | Y16: 28 | Z16: 56 | AA16: 4 | AB16: 4 | AC16: 8 | AD16: =SUM(Z16:AB16) -> 64 | AH16: 1 | AI16: 5 | AM16: 33.057664
A17: 16 | B17: Hoop | C17: sand | D17: J_scrape | E17: B | F17: 21 | G17: 2 | I17: 2 | K17: =F17*4 -> 84 | L17: =H17*4 -> 0 | M17: =I17*4 -> 8 | N17: =J17*4 -> 0 | O17: =M17+N17 -> 8 | P17: =SUM(L17:N17) -> 8 | S17: 10 | T17: 3 | U17: 9 | V17: 0.5 | W17: 0 | X17: 0 | Y17: 40 | Z17: 36 | AA17: 2 | AB17: 0 | AC17: 2 | AD17: =SUM(Z17:AB17) -> 38 | AH17: 3 | AI17: 16 | AM17: 22.94943
A18: 17 | B18: Hoop | C18: sand | D18: J_direct | E18: B | F18: 21 | G18: 3 | I18: 1 | J18: 0.5 | K18: =F18*4 -> 84 | L18: =H18*4 -> 0 | M18: =I18*4 -> 4 | N18: =J18*4 -> 2 | O18: =M18+N18 -> 6 | P18: =SUM(L18:N18) -> 6 | S18: 10 | T18: 1 | U18: 13 | V18: 0.5 | W18: 0 | X18: 1 | Y18: 40 | Z18: 52 | AA18: 2 | AB18: 4 | AC18: 6 | AD18: =SUM(Z18:AB18) -> 58 | AH18: 0 | AI18: 18 | AM18: 31.853018
A19: 18 | B19: Hoop | C19: native | D19: J_direct | E19: B | F19: 16 | G19: 5 | I19: 4 | J19: 0.5 | K19: =F19*4 -> 64 | L19: =H19*4 -> 0 | M19: =I19*4 -> 16 | N19: =J19*4 -> 2 | O19: =M19+N19 -> 18 | P19: =SUM(L19:N19) -> 18 | S19: 4 | T19: 8 | U19: 8 | V19: 4 | W19: 0 | X19: 1 | Y19: 16 | Z19: 32 | AA19: 16 | AB19: 4 | AC19: 20 | AD19: =SUM(Z19:AB19) -> 52 | AH19: 0 | AI19: 17 | AJ19: 667.75749 | AK19: 789.70867 | AL19: 1201.2772 | AM19: 31.164108 | AN19: 18 | AO19: 8.479403 | AP19: 20.7807 | AQ19: 45.671934 | AR19: 667.75749 | AS19: 789.70867 | AT19: 83.20835 | AU19: 1201.2772 | AV19: 14.210583 | AW19: 55.9625
A20: 19 | B20: Hoop | C20: native | D20: no | E20: B | F20: 18 | G20: 5 | I20: 2 | J20: 0.5 | K20: =F20*4 -> 72 | L20: =H20*4 -> 0 | M20: =I20*4 -> 8 | N20: =J20*4 -> 2 | O20: =M20+N20 -> 10 | P20: =SUM(L20:N20) -> 10 | S20: 0 | T20: 6 | U20: 15 | V20: 2 | W20: 0 | X20: 2 | Y20: 0 | Z20: 60 | AA20: 8 | AB20: 8 | AC20: 16 | AD20: =SUM(Z20:AB20) -> 76 | AH20: 0 | AI20: 48.6 | AM20: 41.602164
A21: 20 | B21: Hoop | C21: sand | D21: J_scrape | E21: B | F21: 18 | G21: 5 | I21: 2 | K21: =F21*4 -> 72 | L21: =H21*4 -> 0 | M21: =I21*4 -> 8 | N21: =J21*4 -> 0 | O21: =M21+N21 -> 8 | P21: =SUM(L21:N21) -> 8 | S21: 14 | T21: 6 | U21: 1 | V21: 1 | W21: 0 | X21: 0.5 | Y21: 56 | Z21: 4 | AA21: 4 | AB21: 2 | AC21: 6 | AD21: =SUM(Z21:AB21) -> 10 | AH21: 3 | AI21: 18 | AM21: 5.8733246
A22: 21 | B22: Hoop | C22: sand | D22: J_direct | E22: C | F22: 23 | G22: 2 | K22: =F22*4 -> 92 | L22: =H22*4 -> 0 | M22: =I22*4 -> 0 | N22: =J22*4 -> 0 | O22: =M22+N22 -> 0 | P22: =SUM(L22:N22) -> 0 | S22: 13 | T22: 0 | U22: 0 | V22: 0 | W22: 0 | X22: 0 | Y22: 52 | Z22: 0 | AA22: 0 | AB22: 0 | AC22: 0 | AD22: =SUM(Z22:AB22) -> 0 | AH22: 12 | AI22: 0 | AM22: 17.426135
A23: 22 | B23: Hoop | C23: sand | D23: J_direct | E23: B | F23: 20 | G23: 4 | I23: 1 | J23: 0.5 | K23: =F23*4 -> 80 | L23: =H23*4 -> 0 | M23: =I23*4 -> 4 | N23: =J23*4 -> 2 | O23: =M23+N23 -> 6 | P23: =SUM(L23:N23) -> 6 | S23: 9 | T23: 1 | U23: 10 | V23: 1 | W23: 0 | X23: 0.5 | Y23: 36 | Z23: 40 | AA23: 4 | AB23: 2 | AC23: 6 | AD23: =SUM(Z23:AB23) -> 46 | AH23: 4 | AI23: 42.6 | AM23: 21.660895
A24: 23 | B24: Hoop | C24: native | D24: J_scrape | E24: B | F24: 18 | G24: 5 | I24: 2 | J24: 0.5 | K24: =F24*4 -> 72 | L24: =H24*4 -> 0 | M24: =I24*4 -> 8 | N24: =J24*4 -> 2 | O24: =M24+N24 -> 10 | P24: =SUM(L24:N24) -> 10 | S24: 4 | T24: 0 | U24: 17 | V24: 3 | W24: 0 | X24: 1 | Y24: 16 | Z24: 68 | AA24: 12 | AB24: 4 | AC24: 16 | AD24: =SUM(Z24:AB24) -> 84 | AH24: 0 | AI24: 21 | AM24: 74.137178
A25: 24 | B25: Hoop | C25: native | D25: no | E25: B | F25: 22 | G25: 1 | I25: 2 | J25: 0.5 | K25: =F25*4 -> 88 | L25: =H25*4 -> 0 | M25: =I25*4 -> 8 | N25: =J25*4 -> 2 | O25: =M25+N25 -> 10 | P25: =SUM(L25:N25) -> 10 | S25: 3 | T25: 1 | U25: 18 | V25: 3 | W25: 0.5 | X25: 0.5 | Y25: 12 | Z25: 72 | AA25: 12 | AB25: 2 | AC25: 14 | AD25: =SUM(Z25:AB25) -> 86 | AH25: 0 | AI25: 24.5 | AM25: 53.790378
A26: 25 | B26: Hoop | C26: native | D26: no | E26: B | F26: 16 | G26: 5 | I26: 4 | J26: 0.5 | K26: =F26*4 -> 64 | L26: =H26*4 -> 0 | M26: =I26*4 -> 16 | N26: =J26*4 -> 2 | O26: =M26+N26 -> 18 | P26: =SUM(L26:N26) -> 18 | S26: 6 | T26: 1 | U26: 14 | V26: 2 | W26: 0 | X26: 2 | Y26: 24 | Z26: 56 | AA26: 8 | AB26: 8 | AC26: 16 | AD26: =SUM(Z26:AB26) -> 72 | AH26: 0 | AI26: 50 | AM26: 39.623592
A27: 26 | B27: Hoop | C27: native | D27: J_scrape | E27: B | F27: 15 | G27: 5 | I27: 5 | J27: 0.5 | K27: =F27*4 -> 60 | L27: =H27*4 -> 0 | M27: =I27*4 -> 20 | N27: =J27*4 -> 2 | O27: =M27+N27 -> 22 | P27: =SUM(L27:N27) -> 22 | S27: 0 | T27: 4 | U27: 16 | V27: 3 | W27: 0 | X27: 2 | Y27: 0 | Z27: 64 | AA27: 12 | AB27: 8 | AC27: 20 | AD27: =SUM(Z27:AB27) -> 84 | AH27: 0.5 | AI27: 33.5 | AM27: 23.44174
A28: 27 | B28: Hoop | C28: sand | D28: J_direct | E28: B | F28: 21 | I28: 4 | J28: 0.5 | K28: =F28*4 -> 84 | L28: =H28*4 -> 0 | M28: =I28*4 -> 16 | N28: =J28*4 -> 2 | O28: =M28+N28 -> 18 | P28: =SUM(L28:N28) -> 18 | S28: 7 | T28: 1 | U28: 10 | V28: 2 | W28: 0 | X28: 0.5 | Y28: 28 | Z28: 40 | AA28: 8 | AB28: 2 | AC28: 10 | AD28: =SUM(Z28:AB28) -> 50 | AH28: 5 | AI28: 15 | AM28: 24.913906
A29: 28 | B29: Hoop | C29: native | D29: no | E29: B | F29: 21 | G29: 3 | I29: 1 | J29: 0.5 | K29: =F29*4 -> 84 | L29: =H29*4 -> 0 | M29: =I29*4 -> 4 | N29: =J29*4 -> 2 | O29: =M29+N29 -> 6 | P29: =SUM(L29:N29) -> 6 | S29: 5 | T29: 0 | U29: 13 | V29: 2 | W29: 5 | X29: 0.5 | Y29: 20 | Z29: 52 | AA29: 8 | AB29: 2 | AC29: 10 | AD29: =SUM(Z29:AB29) -> 62 | AH29: 0 | AI29: 21 | AM29: 19.350477
A30: 29 | B30: Hoop | C30: sand | D30: no | E30: B | F30: 22 | G30: 2 | I30: 1 | J30: 0.5 | K30: =F30*4 -> 88 | L30: =H30*4 -> 0 | M30: =I30*4 -> 4 | N30: =J30*4 -> 2 | O30: =M30+N30 -> 6 | P30: =SUM(L30:N30) -> 6 | S30: 12 | T30: 0 | U30: 10 | V30: 2 | W30: 0 | X30: 1 | Y30: 48 | Z30: 40 | AA30: 8 | AB30: 4 | AC30: 12 | AD30: =SUM(Z30:AB30) -> 52 | AH30: 0 | AI30: 35 | AM30: 33.116157
A31: 30 | B31: Hoop | C31: native | D31: J_direct | E31: B | F31: 23 | G31: 2 | I31: 0.5 | J31: 0.5 | K31: =F31*4 -> 92 | L31: =H31*4 -> 0 | M31: =I31*4 -> 2 | N31: =J31*4 -> 2 | O31: =M31+N31 -> 4 | P31: =SUM(L31:N31) -> 4 | S31: 6 | T31: 2 | U31: 11 | V31: 3 | W31: 0 | X31: 1 | Y31: 24 | Z31: 44 | AA31: 12 | AB31: 4 | AC31: 16 | AD31: =SUM(Z31:AB31) -> 60 | AH31: 2 | AI31: 22 | AJ31: 202.56229 | AK31: 259.4147 | AL31: 387.40488 | AM31: 19.451977 | AN31: 30 | AO31: 8.7100693 | AP31: 21.526867 | AQ31: 47.055932 | AR31: 202.56229 | AS31: 259.4147 | AT31: 91.92445 | AU31: 387.40488 | AV31: 15.663267 | AW31: 60.4395
A32: 31 | B32: Hoop | C32: sand | D32: no | E32: B | F32: 20 | G32: 2 | I32: 3 | K32: =F32*4 -> 80 | L32: =H32*4 -> 0 | M32: =I32*4 -> 12 | N32: =J32*4 -> 0 | O32: =M32+N32 -> 12 | P32: =SUM(L32:N32) -> 12 | S32: 14 | T32: 0 | U32: 10 | V32: 0 | W32: 0 | X32: 1 | Y32: 56 | Z32: 40 | AA32: 0 | AB32: 4 | AC32: 4 | AD32: =SUM(Z32:AB32) -> 44 | AH32: 0 | AI32: 23.5 | AM32: 39.009004
A33: 32 | B33: Hoop | C33: native | D33: J_direct | E33: B | F33: 21 | G33: 4 | I33: 0.5 | K33: =F33*4 -> 84 | L33: =H33*4 -> 0 | M33: =I33*4 -> 2 | N33: =J33*4 -> 0 | O33: =M33+N33 -> 2 | P33: =SUM(L33:N33) -> 2 | S33: 4 | T33: 6 | U33: 12 | V33: 0.5 | W33: 0 | X33: 0.5 | Y33: 16 | Z33: 48 | AA33: 2 | AB33: 2 | AC33: 4 | AD33: =SUM(Z33:AB33) -> 52 | AH33: 3 | AI33: 7 | AJ33: 123.05353 | AK33: 263.41043 | AL33: 299.09925 | AM33: 21.471923 | AN33: 32 | AO33: 5.118265 | AP33: 20.543283 | AQ33: 25.505106 | AR33: 123.05353 | AS33: 263.41043 | AT33: 61.92485 | AU33: 299.09925 | AV33: 10.663333 | AW33: 54.538
A34: 33 | B34: Hoop | C34: native | D34: J_direct | E34: B | F34: 14 | G34: 8 | I34: 3 | J34: 0.5 | K34: =F34*4 -> 56 | L34: =H34*4 -> 0 | M34: =I34*4 -> 12 | N34: =J34*4 -> 2 | O34: =M34+N34 -> 14 | P34: =SUM(L34:N34) -> 14 | S34: 1 | T34: 2 | U34: 17 | V34: 1 | W34: 0 | X34: 2 | Y34: 4 | Z34: 68 | AA34: 4 | AB34: 8 | AC34: 12 | AD34: =SUM(Z34:AB34) -> 80 | AH34: 2 | AI34: 9.5 | AJ34: 197.75146 | AK34: 210.74629 | AL34: 369.55458 | AM34: 29.190138 | AN34: 33 | AO34: 8.083975 | AP34: 19.186617 | AQ34: 43.299366 | AR34: 197.75146 | AS34: 210.74629 | AT34: 81.38405 | AU34: 369.55458 | AV34: 13.906533 | AW34: 46.398
A35: 34 | B35: Hoop | C35: native | D35: J_scrape | E35: B | F35: 16 | G35: 5 | I35: 4 | K35: =F35*4 -> 64 | L35: =H35*4 -> 0 | M35: =I35*4 -> 16 | N35: =J35*4 -> 0 | O35: =M35+N35 -> 16 | P35: =SUM(L35:N35) -> 16 | S35: 0 | T35: 3 | U35: 19 | V35: 2 | W35: 0 | X35: 1 | Y35: 0 | Z35: 76 | AA35: 8 | AB35: 4 | AC35: 12 | AD35: =SUM(Z35:AB35) -> 88 | AH35: 0.5 | AI35: 17 | AM35: 37.019525
A36: 35 | B36: Hoop | C36: native | D36: J_scrape | E36: C | F36: 21 | G36: 4 | K36: =F36*4 -> 84 | L36: =H36*4 -> 0 | M36: =I36*4 -> 0 | N36: =J36*4 -> 0 | O36: =M36+N36 -> 0 | P36: =SUM(L36:N36) -> 0 | S36: 17 | T36: 3 | U36: 1 | V36: 0 | W36: 0 | X36: 0 | Y36: 68 | Z36: 4 | AA36: 0 | AB36: 0 | AC36: 0 | AD36: =SUM(Z36:AB36) -> 4 | AH36: 4 | AI36: 0 | AM36: 13.417636
A37: 36 | B37: Hoop | C37: sand | D37: J_scrape | E37: B | F37: 18 | G37: 4 | I37: 3 | K37: =F37*4 -> 72 | L37: =H37*4 -> 0 | M37: =I37*4 -> 12 | N37: =J37*4 -> 0 | O37: =M37+N37 -> 12 | P37: =SUM(L37:N37) -> 12 | S37: 6 | T37: 0 | U37: 15 | V37: 2 | W37: 0 | X37: 2 | Y37: 24 | Z37: 60 | AA37: 8 | AB37: 8 | AC37: 16 | AD37: =SUM(Z37:AB37) -> 76 | AH37: 0 | AI37: 8.5 | AM37: 61.222602
A38: 37 | B38: Quesadilla | C38: native | D38: J_scrape | E38: B | F38: 15 | G38: 3 | I38: 7 | K38: =F38*4 -> 60 | L38: =H38*4 -> 0 | M38: =I38*4 -> 28 | N38: =J38*4 -> 0 | O38: =M38+N38 -> 28 | P38: =SUM(L38:N38) -> 28 | S38: 0 | T38: 0 | U38: 22 | V38: 2 | W38: 0 | X38: 1 | Y38: 0 | Z38: 88 | AA38: 8 | AB38: 4 | AC38: 12 | AD38: =SUM(Z38:AB38) -> 100 | AH38: 0 | AI38: 57.5 | AM38: 48.335581
A39: 38 | B39: Quesadilla | C39: native | D39: no | E39: B | F39: 19 | G39: 2 | I39: 4 | K39: =F39*4 -> 76 | L39: =H39*4 -> 0 | M39: =I39*4 -> 16 | N39: =J39*4 -> 0 | O39: =M39+N39 -> 16 | P39: =SUM(L39:N39) -> 16 | S39: 0 | T39: 0 | U39: 20 | V39: 4 | W39: 0 | X39: 1 | Y39: 0 | Z39: 80 | AA39: 16 | AB39: 4 | AC39: 20 | AD39: =SUM(Z39:AB39) -> 100 | AH39: 0 | AI39: 72.5 | AM39: 53.918509
A40: 39 | B40: Quesadilla | C40: native | D40: no | E40: B | F40: 19 | G40: 4 | I40: 2 | K40: =F40*4 -> 76 | L40: =H40*4 -> 0 | M40: =I40*4 -> 8 | N40: =J40*4 -> 0 | O40: =M40+N40 -> 8 | P40: =SUM(L40:N40) -> 8 | S40: 1 | T40: 1 | U40: 17 | V40: 6 | W40: 0 | X40: 0.5 | Y40: 4 | Z40: 68 | AA40: 24 | AB40: 2 | AC40: 26 | AD40: =SUM(Z40:AB40) -> 94 | AH40: 0 | AI40: 63 | AM40: 43.719934
...

Sheet summary
A1: irrigation type | B1: soil | C1: Jute_noScrapeCat | D1: Inoc | E1: N Rows | F1: Mean(%Bare_1 2) | G1: Mean(% cyano_1 2) | H1: Mean(%lichen 2) | I1: Mean(%moss 2) | J1: Mean(%LS_1 2) | K1: Mean(%TotalBiocrust_1 2) | L1: Mean(% plant) | M1: Mean(Average of LBmg_L) | N1: Mean(Chl a) | O1: Mean(Average of TBmg_L) | P1: Mean(Average of LBug) | Q1: Mean(Average of LBug_g) | R1: Mean(Average of TBug_g) | S1: Mean(Average of Gug) | T1: Mean(Average of Gug_g) | U1: Mean(Average of Gmg_L) | V1: Mean(Average of TBug) | W1: Std Err(%Bare_1 2) | X1: Std Err(% cyano_1 2) | Y1: Std Err(%lichen 2) | Z1: Std Err(%moss 2) | AA1: Std Err(%LS_1 2) | AB1: Std Err(%TotalBiocrust_1 2) | AC1: Std Err(% plant) | AD1: Std Err(Average of LBmg_L) | AE1: Std Err(Chl a) | AF1: Std Err(Average of TBmg_L) | AG1: Std Err(Average of LBug) | AH1: Std Err(Average of LBug_g) | AI1: Std Err(Average of TBug_g) | AJ1: Std Err(Average of Gug) | AK1: Std Err(Average of Gug_g) | AL1: Std Err(Average of Gmg_L) | AM1: Std Err(Average of TBug) | AN1: Mean(%Bare_1) | AO1: Mean(% cyano_1) | AP1: Mean(%lichen) | AQ1: Mean(%moss) | AR1: Mean(%LS_1) | AS1: Mean(%TotalBiocrust_1) | AT1: Std Err(%Bare_1) | AU1: Std Err(% cyano_1) | AV1: Std Err(%lichen) | AW1: Std Err(%moss) | AX1: Std Err(%LS_1) | AY1: Std Err(%TotalBiocrust_1)
A2: GH | B2: native | C2: J | D2: B | E2: 10 | F2: 4.8 | G2: 5 | H2: 0 | I2: 17.6 | J2: 17.6 | K2: 22.6 | L2: 3.85 | M2: 14.188395 | N2: 57.53 | O2: 29.548158 | P2: 79.925884 | Q2: 369.4017 | R2: 498.85682 | S2: 153.6466 | T2: 706.87886 | U2: 25.950292 | V2: 108.56725 | W2: 0.95219046 | X2: 0.9067647 | Y2: 0 | Z2: 1.6 | AA2: 1.6 | AB2: 1.9333333 | AC2: 0.28915586 | AD2: 2.356855 | AE2: 9.4902963 | AF2: 1.182593 | AG2: 14.14113 | AH2: 68.655787 | AI2: 38.457169 | AJ2: 10.592732 | AK2: 54.853599 | AL2: 1.7654553 | AM2: 7.095558 | AN2: 52.8 | AO2: 0 | AP2: 20 | AQ2: 0 | AR2: 20 | AS2: 20 | AT2: 3.9463063 | AU2: 0 | AV2: 2.921187 | AW2: 0 | AX2: 2.921187 | AY2: 2.921187
A3: GH | B3: native | C3: J | D3: C | E3: 2 | F3: 8 | G3: 1 | H3: 0 | I3: 0 | J3: 0 | K3: 1 | L3: 0 | N3: 126.6 | W3: 4 | X3: 1 | Y3: 0 | Z3: 0 | AA3: 0 | AB3: 1 | AC3: 0 | AE3: 19.22 | AN3: 30 | AO3: 0 | AP3: 0 | AQ3: 0 | AR3: 0 | AS3: 0 | AT3: 14 | AU3: 0 | AV3: 0 | AW3: 0 | AX3: 0 | AY3: 0
A4: GH | B4: native | C4: N | D4: B | E4: 5 | F4: 6.8 | G4: 8 | H4: 0 | I4: 13.6 | J4: 13.6 | K4: 21.6 | L4: 3.5 | N4: 24.666 | W4: 2.4979992 | X4: 2.1908902 | Y4: 0 | Z4: 2.712932 | AA4: 2.712932 | AB4: 0.9797959 | AC4: 0.2236068 | AE4: 6.524902 | AN4: 51.2 | AO4: 0 | AP4: 22.4 | AQ4: 0.8 | AR4: 23.2 | AS4: 23.2 | AT4: 5.8514955 | AU4: 0 | AV4: 4.3081318 | AW4: 0.8 | AX4: 4.6303348 | AY4: 4.6303348
A5: GH | B5: native | C5: N | D5: C | E5: 1 | F5: 8 | G5: 0 | H5: 0 | I5: 0 | J5: 0 | K5: 0 | L5: 0 | N5: 40.52 | AN5: 48 | AO5: 0 | AP5: 0 | AQ5: 0 | AR5: 0 | AS5: 0
A6: GH | B6: sand | C6: J | D6: B | E6: 10 | F6: 4.8 | G6: 5.2 | H6: 0 | I6: 20.4 | J6: 20.4 | K6: 25.6 | L6: 3.3 | M6: 41.332879 | N6: 35.039 | O6: 25.088117 | P6: 242.79279 | Q6: 1134.4406 | R6: 382.66703 | S6: 93.14065 | T6: 435.46403 | U6: 15.865967 | V6: 81.807 | W6: 0.74236858 | X6: 0.9977753 | Y6: 0 | Z6: 3.0081371 | AA6: 3.0081371 | AB6: 3.1524241 | AC6: 0.32659863 | AE6: 4.3920088 | AN6: 62.4 | AO6: 0 | AP6: 16.2 | AQ6: 0.4 | AR6: 16.6 | AS6: 16.6 | AT6: 2.6127891 | AU6: 0 | AV6: 2.6741561 | AW6: 0.4 | AX6: 2.7656625 | AY6: 2.7656625
A7: GH | B7: sand | C7: J | D7: C | E7: 2 | F7: 2 | G7: 0 | H7: 0 | I7: 0 | J7: 0 | K7: 0 | L7: 0 | N7: 86.33 | W7: 0 | X7: 0 | Y7: 0 | Z7: 0 | AA7: 0 | AB7: 0 | AC7: 0 | AE7: 0.48 | AN7: 70 | AO7: 0 | AP7: 0 | AQ7: 0 | AR7: 0 | AS7: 0 | AT7: 2 | AU7: 0 | AV7: 0 | AW7: 0 | AX7: 0 | AY7: 0
A8: GH | B8: sand | C8: N | D8: B | E8: 5 | F8: 4 | G8: 4.8 | H8: 0 | I8: 12 | J8: 12 | K8: 16.8 | L8: 2.8 | N8: 34.374 | W8: 1.0954451 | X8: 1.356466 | Y8: 0 | Z8: 4.5607017 | AA8: 4.5607017 | AB8: 4.586938 | AC8: 0.64420494 | AE8: 5.2034264 | AN8: 69.6 | AO8: 0 | AP8: 14.4 | AQ8: 0 | AR8: 14.4 | AS8: 14.4 | AT8: 3.9191836 | AU8: 0 | AV8: 2.712932 | AW8: 0 | AX8: 2.712932 | AY8: 2.712932
A9: GH | B9: sand | C9: N | D9: C | E9: 1 | F9: 2 | G9: 0 | H9: 0 | I9: 0 | J9: 0 | K9: 0 | L9: 0 | N9: 99.9 | AN9: 80 | AO9: 0 | AP9: 0 | AQ9: 0 | AR9: 0 | AS9: 0
A10: Hoop | B10: native | C10: J | D10: B | E10: 10 | F10: 27.2 | G10: 11 | H10: 2.4 | I10: 4 | J10: 6.4 | K10: 17.4 | L10: 28.4 | M10: 7.5979281 | N10: 27.718 | O10: 20.509367 | P10: 40.383085 | Q10: 297.78119 | R10: 380.82002 | S10: 79.610425 | T10: 564.33397 | U10: 13.610929 | V10: 54.3345 | W10: 9.8486322 | X10: 2.1343747 | Y10: 1.6 | Z10: 0.73029674 | AA10: 1.4236104 | AB10: 2.7495454 | AC10: 7.757004 | AD10: 0.8366016 | AE10: 3.5248463 | AF10: 0.48817227 | AG10: 5.0196096 | AH10: 124.66114 | AI10: 136.82083 | AJ10: 6.3278853 | AK10: 213.16836 | AL10: 1.0546475 | AM10: 2.9290336 | AN10: 70.8 | AO10: 0 | AP10: 10 | AQ10: 2.2 | AR10: 12.2 | AS10: 12.2 | AT10: 3.6295087 | AU10: 0 | AV10: 1.9776529 | AW10: 0.69602043 | AX10: 1.9194907 | AY10: 1.9194907
A11: Hoop | B11: native | C11: J | D11: C | E11: 2 | F11: 18 | G11: 0 | H11: 0 | I11: 0 | J11: 0 | K11: 0 | L11: 12.5 | N11: 97.145 | W11: 6 | X11: 0 | Y11: 0 | Z11: 0 | AA11: 0 | AB11: 0 | AC11: 12.5 | AE11: 15.185 | AN11: 76 | AO11: 0 | AP11: 0 | AQ11: 0 | AR11: 0 | AS11: 0 | AT11: 8 | AU11: 0 | AV11: 0 | AW11: 0 | AX11: 0 | AY11: 0
A12: Hoop | B12: native | C12: N | D12: B | E12: 5 | F12: 8.8 | G12: 10.4 | H12: 11.6 | I12: 4.4 | J12: 16 | K12: 26.4 | L12: 36.62 | N12: 34.036 | W12: 4.2708313 | X12: 1.6 | Y12: 7.1665891 | Z12: 1.4696938 | AA12: 6.2928531 | AB12: 7.4135012 | AC12: 5.9961988 | AE12: 11.838568 | AN12: 78.4 | AO12: 0 | AP12: 8.8 | AQ12: 2 | AR12: 10.8 | AS12: 10.8 | AT12: 4.4899889 | AU12: 0 | AV12: 1.9595918 | AW12: 0 | AX12: 1.9595918 | AY12: 1.9595918
A13: Hoop | B13: native | C13: N | D13: C | E13: 1 | F13: 160 | G13: 0 | H13: 0 | I13: 0 | J13: 0 | K13: 0 | L13: 0 | N13: 5.72 | AN13: 80 | AO13: 0 | AP13: 0 | AQ13: 0 | AR13: 0 | AS13: 0
A14: Hoop | B14: sand | C14: J | D14: B | E14: 10 | F14: 6.4 | G14: 10 | H14: 0.8 | I14: 3 | J14: 3.8 | K14: 13.8 | L14: 18.46 | M14: 6.304549 | N14: 23.675 | O14: 20.339783 | P14: 32.62281 | Q14: 158.41232 | R14: 257.73295 | S14: 63.54645 | T14: 306.96719 | U14: 10.9336 | V14: 53.317 | W14: 2.2469733 | X14: 3.3730962 | Y14: 0.8 | Z14: 0.68313005 | AA14: 0.96378882 | AB14: 4.1036569 | AC14: 3.4456801 | AE14: 3.8288046 | AN14: 80 | AO14: 0 | AP14: 8.2 | AQ14: 1.2 | AR14: 9.4 | AS14: 9.4 | AT14: 2.5991452 | AU14: 0 | AV14: 1.3482499 | AW14: 0.32659863 | AX14: 1.334999 | AY14: 1.334999
A15: Hoop | B15: sand | C15: J | D15: C | E15: 2 | F15: 2 | G15: 0 | H15: 0 | I15: 0 | J15: 0 | K15: 0 | L15: 0 | N15: 38.835 | W15: 2 | X15: 0 | Y15: 0 | Z15: 0 | AA15: 0 | AB15: 0 | AC15: 0 | AE15: 15.205 | AN15: 90 | AO15: 0 | AP15: 0 | AQ15: 0 | AR15: 0 | AS15: 0 | AT15: 2 | AU15: 0 | AV15: 0 | AW15: 0 | AX15: 0 | AY15: 0
A16: Hoop | B16: sand | C16: N | D16: B | E16: 5 | F16: 26.4 | G16: 3.6 | H16: 6.4 | I16: 3.2 | J16: 9.6 | K16: 13.2 | L16: 28.5 | N16: 24.76 | W16: 21.525798 | X16: 1.3266499 | Y16: 3.2496154 | Z16: 0.48989795 | AA16: 3.1874755 | AB16: 3.3226495 | AC16: 3.3052988 | AE16: 8.0839118 | AN16: 82.4 | AO16: 0 | AP16: 8 | AQ16: 1.2 | AR16: 9.2 | AS16: 9.2 | AT16: 2.4 | AU16: 0 | AV16: 1.7888544 | AW16: 0.48989795 | AX16: 1.356466 | AY16: 1.356466
A17: Hoop | B17: sand | C17: N | D17: C | E17: 1 | F17: 4 | G17: 0 | H17: 2 | I17: 0 | J17: 2 | K17: 2 | L17: 0 | N17: 61.58 | AN17: 96 | AO17: 0 | AP17: 0 | AQ17: 0 | AR17: 0 | AS17: 0
A18: Quesadilla | B18: native | C18: J | D18: B | E18: 10 | F18: 8 | G18: 7.6 | H18: 0.4 | I18: 4.2 | J18: 4.6 | K18: 12.2 | L18: 40.15 | M18: 13.007054 | N18: 32.618 | O18: 25.454417 | P18: 72.837838 | Q18: 338.94979 | R18: 395.22719 | S18: 114.87009 | T18: 537.59725 | U18: 19.48754 | V18: 84.0048 | W18: 1.7888544 | X18: 1.1075498 | Y18: 0.26666667 | Z18: 1.2454361 | AA18: 1.117537 | AB18: 1.645195 | AC18: 4.0654711 | AD18: 1.8458484 | AE18: 5.8696473 | AF18: 3.2229294 | AG18: 11.07509 | AH18: 53.139646 | AI18: 94.989528 | AJ18: 19.909371 | AK18: 99.497807 | AL18: 3.3182285 | AM18: 19.337576 | AN18: 73.6 | AO18: 0 | AP18: 14.4 | AQ18: 1.2 | AR18: 15.6 | AS18: 15.6 | AT18: 3.4871192 | AU18: 0 | AV18: 2.6127891 | AW18: 0.32659863 | AX18: 2.4729649 | AY18: 2.4729649
A19: Quesadilla | B19: native | C19: J | D19: C | E19: 2 | F19: 34 | G19: 0 | H19: 0 | I19: 0 | J19: 0 | K19: 0 | L19: 0 | N19: 67.31 | W19: 30 | X19: 0 | Y19: 0 | Z19: 0 | AA19: 0 | AB19: 0 | AC19: 0 | AE19: 5.45 | AN19: 68 | AO19: 0 | AP19: 2 | AQ19: 0 | AR19: 2 | AS19: 2 | AT19: 8 | AU19: 0 | AV19: 2 | AW19: 0 | AX19: 2 | AY19: 2
A20: Quesadilla | B20: native | C20: N | D20: B | E20: 5 | F20: 1.6 | G20: 14.4 | H20: 1.2 | I20: 2 | J20: 3.2 | K20: 17.6 | L20: 67.7 | N20: 25.764 | W20: 0.9797959 | X20: 3.7094474 | Y20: 0.8 | Z20: 0.89442719 | AA20: 0.48989795 | AB20: 3.7629775 | AC20: 6.3158531 | AE20: 5.2088047 | AN20: 65.6 | AO20: 0 | AP20: 14.4 | AQ20: 0.4 | AR20: 14.8 | AS20: 14.8 | AT20: 5.3065997 | AU20: 0 | AV20: 2.0396078 | AW20: 0.4 | AX20: 1.9595918 | AY20: 1.9595918
A21: Quesadilla | B21: native | C21: N | D21: C | E21: 1 | F21: 44 | G21: 0 | H21: 2 | I21: 0 | J21: 2 | K21: 2 | L21: 0 | N21: 57.3 | AN21: 56 | AO21: 0 | AP21: 0 | AQ21: 0 | AR21: 0 | AS21: 0
A22: Quesadilla | B22: sand | C22: J | D22: B | E22: 10 | F22: 0.4 | G22: 8.6 | H22: 1.4 | I22: 1.8 | J22: 3.2 | K22: 11.8 | L22: 49.9 | N22: 34.796 | W22: 0.4 | X22: 1.2666667 | Y22: 0.52068331 | Z22: 0.81377037 | AA22: 0.61101009 | AB22: 1.5902481 | AC22: 4.502962 | AE22: 5.6870264 | AN22: 77.2 | AO22: 0 | AP22: 13.6 | AQ22: 1.4 | AR22: 15 | AS22: 15 | AT22: 2.6025628 | AU22: 0 | AV22: 1.7074998 | AW22: 0.30550505 | AX22: 1.8439089 | AY22: 1.8439089
A23: Quesadilla | B23: sand | C23: J | D23: C | E23: 2 | F23: 0 | G23: 0 | H23: 0 | I23: 0 | J23: 0 | K23: 0 | L23: 0 | N23: 45.075 | W23: 0 | X23: 0 | Y23: 0 | Z23: 0 | AA23: 0 | AB23: 0 | AC23: 0 | AE23: 26.845 | AN23: 96 | AO23: 0 | AP23: 0 | AQ23: 0 | AR23: 0 | AS23: 0 | AT23: 4 | AU23: 0 | AV23: 0 | AW23: 0 | AX23: 0 | AY23: 0
A24: Quesadilla | B24: sand | C24: N | D24: B | E24: 5 | F24: 0.8 | G24: 10.4 | H24: 1.6 | I24: 1.6 | J24: 3.2 | K24: 13.6 | L24: 49.7 | N24: 39.934 | W24: 0.8 | X24: 1.6 | Y24: 0.9797959 | Z24: 0.74833148 | AA24: 0.48989795 | AB24: 1.4696938 | AC24: 4.9335586 | AE24: 5.7470537 | AN24: 78.4 | AO24: 0 | AP24: 10.4 | AQ24: 1.2 | AR24: 11.6 | AS24: 11.6 | AT24: 4.1182521 | AU24: 0 | AV24: 3.7094474 | AW24: 0.48989795 | AX24: 3.6551334 | AY24: 3.6551334
A25: Quesadilla | B25: sand | C25: N | D25: C | E25: 1 | F25: 0 | G25: 0 | H25: 0 | I25: 0 | J25: 0 | K25: 0 | L25: 0 | N25: 68.26 | AB25: =AVERAGE(AB2,AB4,AB6,AB8,AB10,AB12,AB14,AB16,AB18,AB20,AB22,AB24) -> 3.0591632 | AN25: 96 | AO25: 0 | AP25: 0 | AQ25: 0 | AR25: 0 | AS25: 0
K26: =AVERAGE(K4,K6,K8,K10,K12,K14,K16,K18,K20,K22,K24) -> 17.272727
C31: irrigation type | D31: N Rows | E31: Mean(%Cyano_2) | F31: Mean(% Lichen_2) | G31: Mean(% Moss_2) | H31: Mean(TTL biocurst_2) | I31: Std Err(%Cyano_2) | J31: Std Err(% Lichen_2) | K31: Std Err(% Moss_2) | L31: Std Err(TTL biocurst_2)
C32: GH | D32: 36 | E32: 59.611111 | F32: 4.6666667 | G32: 14.111111 | H32: 78.388889 | I32: 3.796255 | J32: 0.61204834 | K32: 1.6289922 | L32: 5.0970389
C33: Hoop | D33: 36 | E33: 34.388889 | F33: 7.1666667 | G33: 3 | H33: 44.555556 | I33: 3.9783696 | J33: 0.93052298 | K33: 0.41018772 | L33: 4.6212835
C34: Quesadilla | D34: 36 | E34: 65.444444 | F34: 7.9444444 | G34: 2.1666667 | H34: 75.555556 | I34: 5.2954674 | J34: 0.97748011 | K34: 0.48713611 | L34: 5.8771071
C43: irrigation type | D43: soil | E43: Jute_noScrapeCat | F43: N Rows | G43: Mean(%Cyano_2) | H43: Mean(% Lichen_2) | I43: Mean(% Moss_2) | J43: Mean(%LS_2) | K43: Mean(TTL biocurst_2) | L43: Std Err(%Cyano_2) | M43: Std Err(% Lichen_2) | N43: Std Err(% Moss_2) | O43: Std Err(%LS_2) | P43: Std Err(TTL biocurst_2)
C44: GH | D44: sand | E44: N | F44: 6 | G44: 63.666667 | H44: 4 | I44: 10 | J44: 14 | K44: 77.666667 | L44: 12.462388 | M44: 1.3662601 | N44: 4.226898 | O44: 4.6761808 | P44: 15.365907
C45: GH | D45: sand | E45: J | F45: 12 | G45: 55.333333 | H45: 4.3333333 | I45: 17 | J45: 21.333333 | K45: 76.666667 | L45: 7.8134823 | M45: 1.0100505 | N45: 3.3799767 | O45: 3.879498 | P45: 10.754374
C46: GH | D46: native | E46: N | F46: 6 | G46: 56 | H46: 6.6666667 | I46: 11.333333 | J46: 18 | K46: 74 | L46: 8.326664 | M46: 2.2310934 | N46: 3.1692972 | O46: 3.6878178 | P46: 11.944315
C47: GH | D47: native | E47: J | F47: 12 | G47: 63.666667 | H47: 4.3333333 | I47: 14.666667 | J47: 19 | K47: 82.666667 | L47: 4.5781651 | M47: 0.8819171 | N47: 2.3783536 | O47: 2.9076701 | P47: 6.5889408
C49: Quesadilla | D49: sand | E49: N | F49: 6 | G49: 68 | H49: 8.6666667 | I49: 1.3333333 | J49: 10 | K49: 78 | L49: 13.779211 | M49: 2.1705094 | N49: 0.66666667 | O49: 2.4221203 | P49: 15.646086
C50: Quesadilla | D50: sand | E50: J | F50: 12 | G50: 68 | H50: 7.1666667 | I50: 1.5 | J50: 8.6666667 | K50: 76.666667 | L50: 10.17424 | M50: 1.4240006 | N50: 0.70172947 | O50: 1.8963016 | P50: 10.952607
C51: Quesadilla | D51: native | E51: N | F51: 6 | G51: 66 | H51: 12 | I51: 1.6666667 | J51: 13.666667 | K51: 79.666667 | L51: 14.075984 | M51: 3.8643671 | N51: 0.80277297 | O51: 4.5141752 | P51: 16.036763
C52: Quesadilla | D52: native | E52: J | F52: 12 | G52: 61.333333 | H52: 6.3333333 | I52: 3.5 | J52: 9.8333333 | K52: 71.166667 | L52: 8.5752757 | M52: 1.251262 | N52: 1.1315048 | O52: 2.0069324 | P52: 9.6309423
C54: Hoop | D54: sand | E54: N | F54: 6 | G54: 21.666667 | H54: 4.6666667 | I54: 2.6666667 | J54: 7.3333333 | K54: 29 | L54: 7.2372493 | M54: 1.9090428 | N54: 0.66666667 | O54: 2.1081851 | P54: 7.7244202
...

Sheet stats table
A1: stats table
B2: % Bare | D2: % Plants | F2: % Cyanobacteria | H2: % Lichen | J2: % Moss | L2: % Total Biocrust | N2: Chlorophyll a | P2: LB EPS ug/G | R2: TB EPS ug/G | T2: Total EPS ug/G
B3: F Ratio | C3: Prob > F | D3: F Ratio | E3: Prob > F | F3: F Ratio | G3: Prob > F | H3: F Ratio | I3: Prob > F | J3: F Ratio | K3: Prob > F | L3: F Ratio | M3: Prob > F | N3: F Ratio | O3: Prob > F | P3: F Ratio | R3: F Ratio | S3: Prob > F | T3: F Ratio | U3: Prob > F
A4: Irrigation Type | B4: 57.9 | C4: <.0001 | D4: 101.5586 | E4: <.0001 | F4: 50.4221 | G4: <.0001 | H4: 7.2195 | I4: 0.0013 | J4: 58.6815 | K4: <.0001 | L4: 70.2109 | M4: <.0001 | N4: 22.94 | O4: <.0001 | P4: 2.9661 | Q4: 0.05 | R4: 0.7989 | S4: 0.5807 | T4: 1.4237 | U4: 0.2522
A5: Soil Typle | B5: 21.3 | C5: <.0001 | D5: 2.7326 | E5: 0.1023 | F5: 0.5268 | G5: 0.4701 | H5: 5.9119 | I5: 0.0173 | J5: 0.3172 | K5: 0.5749 | L5: 3.0781 | M5: 0.0833 | N5: 18.51 | O5: <.0001
A6: Jute | B6: 0.1 | C6: 0.8038 | D6: 7.2077 | E6: 0.0089 | F6: 0.1553 | G6: 0.6946 | H6: 2.5906 | I6: 0.1115 | J6: 4.43 | K6: 0.0385 | L6: 0.0236 | M6: 0.8784 | N6: 2.57 | O6: 0.112
A7: Irrigation * Soil | B7: 18.8 | C7: <.0001 | D7: 0.7696 | E7: 0.4667 | F7: 5.0709 | G7: 0.0085 | H7: 0.7928 | I7: 0.4562 | J7: 0.3067 | K7: 0.7368 | L7: 7.5238 | M7: 0.001 | N7: 8.39 | O7: 0.0004
A8: irrigation * Jute | B8: 1 | C8: 0.3704 | D8: 2.236 | E8: 0.1137 | F8: 0.1553 | G8: 0.8565 | H8: 2.3971 | I8: 0.0977 | J8: 3.0538 | K8: 0.0529 | L8: 0.8694 | M8: 0.4232 | N8: 2.01 | O8: 0.14
A9: Soil*Jute | B9: 2.4 | C9: 0.1233 | D9: 2.447 | E9: 0.1218 | F9: 0.5268 | G9: 0.4701 | H9: 2.8158 | I9: 0.0973 | J9: 0.1485 | K9: 0.701 | L9: 2.095 | M9: 0.1518 | N9: 0.15 | O9: 0.9
A10: Soil * Jute * Irrigation | B10: 4.0236 | C10: 0.0217 | D10: 2.9501 | E10: 0.0582 | F10: 2.9834 | G10: 0.0564 | H10: 0.2862 | I10: 0.7519 | J10: 0.6969 | K10: 0.5012 | L10: 2.3378 | M10: 0.1033 | N10: 0.65 | O10: 0.52
A16: irrigation type | B16: soil | C16: jute | D16: Inoc | E16: N Rows | F16: Mean(%Bare_1 2) | G16: Mean(% cyano_1 2) | H16: Mean(%lichen 2) | I16: Mean(%moss 2) | J16: Mean(%LS_1 2) | K16: Mean(%TotalBiocrust_1 2) | L16: Mean(% plant) | N16: Mean(Chl a) | O16: Mean(Average of LBug_g) | P16: Mean(Average of TBug_g) | Q16: Mean(Average of Gug_g) | R16: Std Err(%Bare_1 2) | S16: Std Err(%Bare_1 2) | T16: Std Err(% cyano_1 2) | U16: Std Err(%lichen 2) | V16: Std Err(%moss 2) | W16: Std Err(%LS_1 2) | X16: Std Err(%TotalBiocrust_1 2) | Y16: Std Err(% plant) | Z16: STD Chl a | AA16: Std Err(Average of LBug_g) | AB16: Std Err(Average of TBug_g) | AC16: Std Err(Average of Gug_g) | AD16: Std Err(Average of TBug)
A17: GH | B17: native | C17: J | D17: B | E17: 10 | F17: 4 | G17: 69.6 | H17: 5 | I17: 17.6 | J17: 22.6 | K17: 92.2 | L17: 3.85 | N17: 85.128709 | O17: 522.40948 | P17: 475.61886 | Q17: 652.5959 | R17: 0.95219046 | S17: 0.51639778 | T17: 2.5438379 | U17: 0.9067647 | V17: 1.6 | W17: 1.9333333 | X17: 1.4126413 | Y17: 0.28915586 | Z17: 5.6970789 | AA17: 161.98627 | AB17: 37.780617 | AC17: 68.934685 | AD17: 7.095558
A18: GH | B18: native | C18: J | D18: C | E18: 2 | F18: 48 | G18: 34 | H18: 1 | I18: 0 | J18: 1 | K18: 35 | L18: 0 | N18: 102.16825 | R18: 4 | S18: 8 | T18: 6 | U18: 1 | V18: 0 | W18: 1 | X18: 7 | Y18: 0 | Z18: 15.359993
A19: GH | B19: native | C19: no | D19: B | E19: 5 | F19: 8.4 | G19: 64 | H19: 8 | I19: 13.6 | J19: 21.6 | K19: 85.6 | L19: 3.5 | N19: 72.283018 | R19: 2.4979992 | S19: 1.8330303 | T19: 2.8284271 | U19: 2.1908902 | V19: 2.712932 | W19: 0.9797959 | X19: 3.4871192 | Y19: 0.2236068 | Z19: 19.017651
A20: GH | B20: native | C20: no | D20: C | E20: 1 | F20: 76 | G20: 16 | H20: 0 | I20: 0 | J20: 0 | K20: 16 | L20: 0 | N20: 25.385529
A21: GH | B21: sand | C21: J | D21: B | E21: 10 | F21: 6.8 | G21: 66.4 | H21: 5.2 | I21: 20.4 | J21: 25.6 | K21: 92 | L21: 3.3 | N21: 48.333525 | R21: 0.74236858 | S21: 2.8936713 | T21: 2.8095077 | U21: 0.9977753 | V21: 3.0081371 | W21: 3.1524241 | X21: 3.5901099 | Y21: 0.32659863 | Z21: 4.0660957
A22: GH | B22: sand | C22: J | D22: C | E22: 2 | F22: 100 | G22: 0 | H22: 0 | I22: 0 | J22: 0 | K22: 0 | L22: 0 | N22: 14.672993 | R22: 0 | S22: 0 | T22: 0 | U22: 0 | V22: 0 | W22: 0 | X22: 0 | Y22: 0 | Z22: 8.9520654
A23: GH | B23: sand | C23: no | D23: B | E23: 5 | F23: 5.6 | G23: 76 | H23: 4.8 | I23: 12 | J23: 16.8 | K23: 92.8 | L23: 2.8 | N23: 35.270335 | R23: 1.0954451 | S23: 1.9390719 | T23: 2.1908902 | U23: 1.356466 | V23: 4.5607017 | W23: 4.586938 | X23: 3.2619013 | Y23: 0.64420494 | Z23: 4.051152
A24: GH | B24: sand | C24: no | D24: C | E24: 1 | F24: 100 | G24: 2 | H24: 0 | I24: 0 | J24: 0 | K24: 2 | L24: 0 | N24: 18.234003
A25: Hoop | B25: native | C25: J | D25: B | E25: 10 | F25: 20 | G25: 44 | H25: 10.6 | I25: 4 | J25: 14.6 | K25: 58.6 | L25: 28.4 | N25: 34.393271 | O25: 269.90742 | P25: 356.20261 | Q25: 512.86061 | R25: 1.7888544 | S25: 5.2998952 | T25: 8 | U25: 1.4621141 | V25: 0.73029674 | W25: 1.492202 | X25: 7.8827519 | Y25: 7.757004 | Z25: 5.4330929 | AA25: 100.50466 | AB25: 108.80248 | AC25: 172.95651 | AD25: 19.337576
A26: Hoop | B26: native | C26: J | D26: C | E26: 2 | F26: 58 | G26: 4 | H26: 0 | I26: 0 | J26: 0 | K26: 4 | L26: 12.5 | N26: 10.323939 | R26: 30 | S26: 10 | T26: 0 | U26: 0 | V26: 0 | W26: 0 | X26: 0 | Y26: 12.5 | Z26: 3.0936966
A27: Hoop | B27: native | C27: no | D27: B | E27: 5 | F27: 12 | G27: 54.4 | H27: 10.4 | I27: 4.4 | J27: 14.8 | K27: 69.2 | L27: 36.62 | N27: 35.273188 | R27: 0.9797959 | S27: 4.5607017 | T27: 6.5238026 | U27: 1.6 | V27: 1.4696938 | W27: 1.356466 | X27: 6.1514226 | Y27: 5.9961988 | Z27: 6.4482412
A28: Hoop | B28: native | C28: no | D28: C | E28: 1 | F28: 80 | G28: 0 | H28: 0 | I28: 0 | J28: 0 | K28: 0 | L28: 0 | N28: 12.478133
A29: Hoop | B29: sand | C29: J | D29: B | E29: 10 | F29: 36.8 | G29: 38.8 | H29: 7.2 | I29: 3 | J29: 10.2 | K29: 49 | L29: 18.46 | N29: 30.027394 | R29: 0.4 | S29: 3.2 | T29: 5.0261538 | U29: 1.7435596 | V29: 0.68313005 | W29: 2.0099751 | X29: 5.6430882 | Y29: 3.4456801 | Z29: 4.4740739
A30: Hoop | B30: sand | C30: J | D30: C | E30: 2 | F30: 62 | G30: 0 | H30: 0 | I30: 0 | J30: 0 | K30: 0 | L30: 0 | N30: 12.438375 | R30: 0 | S30: 10 | T30: 0 | U30: 0 | V30: 0 | W30: 0 | X30: 0 | Y30: 0 | Z30: 4.9877596
A31: Hoop | B31: sand | C31: no | D31: B | E31: 5 | F31: 52 | G31: 26 | H31: 5.6 | I31: 3.2 | J31: 8.8 | K31: 34.8 | L31: 28.5 | N31: 25.789711 | R31: 0.8 | S31: 1.7888544 | T31: 7.0992957 | U31: 2.0396078 | V31: 0.48989795 | W31: 1.8547237 | X31: 6.2481997 | Y31: 3.3052988 | Z31: 4.4475859
A32: Hoop | B32: sand | C32: no | D32: C | E32: 1 | F32: 96 | G32: 0 | H32: 0 | I32: 0 | J32: 0 | K32: 0 | L32: 0 | N32: 1.7377691
A33: Quesadilla | B33: native | C33: J | D33: B | E33: 10 | F33: 7.2 | G33: 73.2 | H33: 7.6 | I33: 4.2 | J33: 11.8 | K33: 85 | L33: 40.15 | N33: 37.005284 | O33: 338.94979 | P33: 395.22719 | Q33: 537.59725 | R33: 9.8486322 | S33: 2.1333333 | T33: 3.7261836 | U33: 1.1075498 | V33: 1.2454361 | W33: 1.8245243 | X33: 2.8944391 | Y33: 4.0654711 | Z33: 5.0857783 | AA33: 53.139646 | AB33: 94.989528 | AC33: 99.497807 | AD33: 2.9290336
A34: Quesadilla | B34: native | C34: J | D34: C | E34: 2 | F34: 56 | G34: 2 | H34: 0 | I34: 0 | J34: 0 | K34: 2 | L34: 0 | N34: 8.7956708 | R34: 6 | S34: 24 | T34: 2 | U34: 0 | V34: 0 | W34: 0 | X34: 2 | Y34: 0 | Z34: 3.5506158
A35: Quesadilla | B35: native | C35: no | D35: B | E35: 5 | F35: 2.4 | G35: 79.2 | H35: 14.4 | I35: 2 | J35: 16.4 | K35: 95.6 | L35: 67.7 | N35: 38.137531 | R35: 4.2708313 | S35: 1.6 | T35: 5.9866518 | U35: 3.7094474 | V35: 0.89442719 | W35: 4.4 | X35: 2.2271057 | Y35: 6.3158531 | Z35: 5.5336032
A36: Quesadilla | B36: native | C36: no | D36: C | E36: 1 | F36: 56 | G36: 0 | H36: 0 | I36: 0 | J36: 0 | K36: 0 | L36: 0 | N36: 18.686313
A37: Quesadilla | B37: sand | C37: J | D37: B | E37: 10 | F37: 7.2 | G37: 81.6 | H37: 8.6 | I37: 1.8 | J37: 10.4 | K37: 92 | L37: 49.9 | N37: 33.995129 | R37: 2.2469733 | S37: 4.3736585 | T37: 5.3399958 | U37: 1.2666667 | V37: 0.81377037 | W37: 1.8086213 | X37: 4.3817805 | Y37: 4.502962 | Z37: 4.3505526
A38: Quesadilla | B38: sand | C38: J | D38: C | E38: 2 | F38: 92 | G38: 0 | H38: 0 | I38: 0 | J38: 0 | K38: 0 | L38: 0 | N38: 9.9772161 | R38: 2 | S38: 4 | T38: 0 | U38: 0 | V38: 0 | W38: 0 | X38: 0 | Y38: 0 | Z38: 1.0148264
A39: Quesadilla | B39: sand | C39: no | D39: B | E39: 5 | F39: 4.8 | G39: 81.6 | H39: 10.4 | I39: 1.6 | J39: 12 | K39: 93.6 | L39: 49.7 | N39: 33.880603 | R39: 21.525798 | S39: 2.3323808 | T39: 2.712932 | U39: 1.6 | V39: 0.74833148 | W39: 1.6733201 | X39: 1.4696938 | Y39: 4.9335586 | Z39: 5.0088348
A40: Quesadilla | B40: sand | C40: no | D40: C | E40: 1 | F40: 100 | G40: 0 | H40: 0 | I40: 0 | J40: 0 | K40: 0 | L40: 0 | N40: 1.9931369
A43: irrigation type | B43: soil type | C43: Jute/No | D43: Inoculum | E43: Replicates | F43: % Bare soil | G43: % Cyanobacteria | H43: % Lichen | I43: % Moss | J43: % LS | K43: %Total Biocrust | L43: % Plants | M43: Chlorophyll a (ug/g soil) | N43: Loosely Bound EPS (ug/g soil) | O43: Tightly bound EPS (Ug/g soil) | P43: Sheath PS (ug/g soil) | T43: Mean(LBug_g) | U43: Mean(TBug_g) | V43: Mean(Gug_g) | W43: Mean(EPS total ug_G) | X43: Std Err(LBug_g) | Y43: Std Err(TBug_g) | Z43: Std Err(Gug_g) | AA43: Std Err(EPS total ug_G)
A44: GH | B44: Native | C44: Jute | D44: Biocrust | E44: 10 | F44: =CONCATENATE(F71, " (", R71, ")") -> 4.0 (1.0) | G44: =CONCATENATE(G71, " (", S71, ")") -> 69.6 (0.5) | H44: =CONCATENATE(H71, " (", T71, ")") -> 5.0 (2.5) | I44: =CONCATENATE(I71, " (", U71, ")") -> 17.6 (0.9) | J44: =CONCATENATE(J71, " (", V71, ")") -> 22.6 (1.6) | K44: =CONCATENATE(K71, " (", W71, ")") -> 92.2 (1.4) | L44: =CONCATENATE(L71, " (", X71, ")") -> 3.9 (0.3) | M44: =CONCATENATE(N71, " (", Y71, ")") -> 85.1 (5.7) | N44: =CONCATENATE(T44, " (", X44, ")") -> 522.4 (88.5) | O44: =CONCATENATE(U44, " (", Y44, ")") -> 475.6 (22.8) | P44: =CONCATENATE(V44, " (", Z44, ")") -> 652.6 (40.9) | T44: =TEXT(summary!C148,"#,#0.0") -> 522.4 | U44: =TEXT(summary!D148,"#,#0.0") -> 475.6 | V44: =TEXT(summary!E148,"#,#0.0") -> 652.6 | W44: =TEXT(summary!F148,"#,#0.0") -> 1,650.6 | X44: =TEXT(summary!G148,"#,#0.0") -> 88.5 | Y44: =TEXT(summary!H148,"#,#0.0") -> 22.8 | Z44: =TEXT(summary!I148,"#,#0.0") -> 40.9 | AA44: =TEXT(summary!J148,"#,#0.0") -> 82.9
A45: GH | B45: Native | C45: Jute | D45: Control | E45: 2 | F45: =CONCATENATE(F72, " (", R72, ")") -> 48.0 (4.0) | G45: =CONCATENATE(G72, " (", S72, ")") -> 34.0 (8.0) | H45: =CONCATENATE(H72, " (", T72, ")") -> 1.0 (6.0) | I45: =CONCATENATE(I72, " (", U72, ")") -> 0.0 (1.0) | J45: =CONCATENATE(J72, " (", V72, ")") -> 1.0 (0.0) | K45: =CONCATENATE(K72, " (", W72, ")") -> 35.0 (7.0) | L45: =CONCATENATE(L72, " (", X72, ")") -> 0.0 (0.0) | M45: =CONCATENATE(N72, " (", Y72, ")") -> 102.2 (15.4) | T45: =TEXT(summary!C149,"#,#0.0") -> 339.0 | U45: =TEXT(summary!D149,"#,#0.0") -> 395.2 | V45: =TEXT(summary!E149,"#,#0.0") -> 537.6 | W45: =TEXT(summary!F149,"#,#0.0") -> 1,271.8 | X45: =TEXT(summary!G149,"#,#0.0") -> 33.4 | Y45: =TEXT(summary!H149,"#,#0.0") -> 53.6 | Z45: =TEXT(summary!I149,"#,#0.0") -> 54.7 | AA45: =TEXT(summary!J149,"#,#0.0") -> 132.3
A46: GH | B46: Native | C46: No Jute | D46: Biocrust | E46: 5 | F46: =CONCATENATE(F73, " (", R73, ")") -> 8.4 (2.5) | G46: =CONCATENATE(G73, " (", S73, ")") -> 64.0 (1.8) | H46: =CONCATENATE(H73, " (", T73, ")") -> 8.0 (2.8) | I46: =CONCATENATE(I73, " (", U73, ")") -> 13.6 (2.2) | J46: =CONCATENATE(J73, " (", V73, ")") -> 21.6 (2.7) | K46: =CONCATENATE(K73, " (", W73, ")") -> 85.6 (3.5) | L46: =CONCATENATE(L73, " (", X73, ")") -> 3.5 (0.2) | M46: =CONCATENATE(N73, " (", Y73, ")") -> 72.3 (19.0) | T46: =TEXT(summary!C150,"#,#0.0") -> 269.9 | U46: =TEXT(summary!D150,"#,#0.0") -> 356.2 | V46: =TEXT(summary!E150,"#,#0.0") -> 512.9 | W46: =TEXT(summary!F150,"#,#0.0") -> 1,139.0 | X46: =TEXT(summary!G150,"#,#0.0") -> 91.0 | Y46: =TEXT(summary!H150,"#,#0.0") -> 102.6 | Z46: =TEXT(summary!I150,"#,#0.0") -> 160.1 | AA46: =TEXT(summary!J150,"#,#0.0") -> 352.4
A47: GH | B47: Native | C47: No Jute | D47: Control | E47: 1 | F47: =CONCATENATE(F74, " (", R74, ")") -> 76.0 (0.0) | G47: =CONCATENATE(G74, " (", S74, ")") -> 16.0 (0.0) | H47: =CONCATENATE(H74, " (", T74, ")") -> 0.0 (0.0) | I47: =CONCATENATE(I74, " (", U74, ")") -> 0.0 (0.0) | J47: =CONCATENATE(J74, " (", V74, ")") -> 0.0 (0.0) | K47: =CONCATENATE(K74, " (", W74, ")") -> 16.0 (0.0) | L47: =CONCATENATE(L74, " (", X74, ")") -> 0.0 (0.0) | M47: =CONCATENATE(N74, " (", Y74, ")") -> 25.4 (0.0)
...

Sheet Sheet1
A3: Row Labels | B3: Average of LBmg_L | C3: Average of TBmg_L | D3: Average of LBug | E3: Average of LBug_g | F3: Average of TBug_g | G3: Average of Gug | H3: Average of Gug_g | I3: Average of Gmg_L | J3: Average of TBug
A4: 4 | B4: 6.304549 | C4: 20.339783 | D4: 32.62281 | E4: 158.41232 | F4: 257.73295 | G4: 63.54645 | H4: 306.96719 | I4: 10.9336 | J4: 53.317
A5: 18 | B5: 8.479403 | C5: 20.7807 | D5: 45.671934 | E5: 667.75749 | F5: 789.70867 | G5: 83.20835 | H5: 1201.2772 | I5: 14.210583 | J5: 55.9625
A6: 30 | B6: 8.7100693 | C6: 21.526867 | D6: 47.055932 | E6: 202.56229 | F6: 259.4147 | G6: 91.92445 | H6: 387.40488 | I6: 15.663267 | J6: 60.4395
A7: 32 | B7: 5.118265 | C7: 20.543283 | D7: 25.505106 | E7: 123.05353 | F7: 263.41043 | G7: 61.92485 | H7: 299.09925 | I7: 10.663333 | J7: 54.538
A8: 33 | B8: 8.083975 | C8: 19.186617 | D8: 43.299366 | E8: 197.75146 | F8: 210.74629 | G8: 81.38405 | H8: 369.55458 | I8: 13.906533 | J8: 46.398
A9: 43 | B9: 12.697302 | C9: 22.680033 | D9: 70.979326 | E9: 335.94295 | F9: 319.23439 | G9: 91.92445 | H9: 434.76721 | I9: 15.663267 | J9: 67.3585
A10: 50 | B10: 14.279014 | C10: 28.1067 | D10: 80.469598 | E10: 369.93843 | F10: 458.97213 | G10: 130.23475 | H10: 600.25769 | I10: 22.048317 | J10: 99.9185
A11: 51 | B11: 6.502263 | C11: 19.322283 | D11: 33.809094 | E11: 161.49789 | F11: 225.90835 | G11: 70.03285 | H11: 334.19666 | I11: 12.014667 | J11: 47.212
A12: 64 | B12: 17.870818 | C12: 36.823283 | D12: 102.02042 | E12: 493.83242 | F12: 736.47988 | G12: 184.55835 | H12: 896.51196 | I12: 31.10225 | J12: 152.218
A13: 71 | B13: 13.685872 | C13: 20.339783 | D13: 76.910746 | E13: 333.53723 | F13: 235.54119 | G13: 97.60005 | H13: 422.25274 | I13: 16.6092 | J13: 53.317
A14: 92 | B14: 10.456543 | C14: 26.207367 | D14: 57.534774 | E14: 254.08068 | F14: 389.0157 | G14: 129.62665 | H14: 573.2282 | I14: 21.946967 | J14: 88.5225
A15: 96 | B15: 10.357686 | C15: 29.768617 | D15: 56.941632 | E15: 263.70447 | F15: 508.56261 | G15: 165.70725 | H15: 766.33429 | I15: 27.9604 | J15: 109.89
... A18: 108 | B18: 20.144529 | C18: 30.514783 | D18: 115.66269 | E18: 541.83025 | F18: 531.97411 | G18: 176.24765 | H18: 821.29755 | I18: 29.717133 | J18: 114.367
A19: blank | B19: 0.867414 | C19: 11.453617 | D19: 5.204484 | E19: #DIV/0! | F19: #DIV/0! | G19: 2.05515 | H19: #DIV/0! | I19: 0.342525 | J19: 68.7217
A20: Grand Total | B20: 12.542838 | C20: 24.023981 | D20: 70.377822 | E20: 377.0889 | F20: 409.01622 | G20: 106.30441 | H20: 567.68459 | I20: 18.045351 | J20: 79.717294

Sheet EPS
A1: plot # | B1: irrigation type | C1: soil | D1: jute | E1: Inoc | F1: Date ran | G1: Plot number | H1: irrigation type | I1: soil | J1: jute | K1: inoc | L1: rep | M1: weight | N1: LB | O1: TB | P1: G | Q1: LBmg_L | R1: LBug | S1: LBug_g | T1: TBmg_L | U1: TBug | V1: TBug_g | W1: Gmg_L | X1: Gug | Y1: Gug_g | AA1: Date | AB1: Conc | AC1: Abs
A2: 4 | B2: Hoop | C2: native | D2: J_direct | E2: B | F2: 43661 | G2: 4 | H2: Hoop | I2: native | J2: J_direct | K2: B | L2: 1 | M2: 200.8 | N2: 0.07 | O2: 0.105 | P2: 0.097 | Q2: =(AA$4*N2)+AA$5 -> 7.58969 | R2: =(((Q2/1000)*6)*1000)-AVERAGE(R$47:R$49) -> 40.333656 | S2: =R2/(M2/1000) -> 200.86482 | T2: =(AA$13*(O2+0.1))+AA$14 -> 20.47545 | U2: =(((T2/1000)*6)*1000)-AVERAGE(U$47:U$49) -> 54.131 | V2: =U2/(M2/1000) -> 269.57669 | W2: =(AA$22*P2)+AA$23 -> 9.61605 | X2: =(((W2/1000)*6)*1000)-AVERAGE(X$47:X$49) -> 55.64115 | Y2: =X2/(M2/1000) -> 277.09736 | AA2: 43661 | AB2: 0 | AC2: -0.001
F3: 43661 | G3: 4 | H3: Hoop | I3: native | J3: J_direct | K3: B | L3: 2 | M3: 212.2 | N3: 0.05 | O3: 0.117 | P3: 0.115 | Q3: =(AA$4*N3)+AA$5 -> 5.61255 | R3: =(((Q3/1000)*6)*1000)-AVERAGE(R$47:R$49) -> 28.470816 | S3: =R3/(M3/1000) -> 134.16973 | T3: =(AA$13*(O3+0.1))+AA$14 -> 21.69645 | U3: =(((T3/1000)*6)*1000)-AVERAGE(U$47:U$49) -> 61.457 | V3: =U3/(M3/1000) -> 289.61828 | W3: =(AA$22*P3)+AA$23 -> 11.44035 | X3: =(((W3/1000)*6)*1000)-AVERAGE(X$47:X$49) -> 66.58695 | Y3: =X3/(M3/1000) -> 313.79336 | AB3: 5 | AC3: 0.042
F4: 43661 | G4: 4 | H4: Hoop | I4: native | J4: J_direct | K4: B | L4: 3 | M4: 207.3 | N4: 0.051 | O4: 0.089 | P4: 0.118 | Q4: =(AA$4*N4)+AA$5 -> 5.711407 | R4: =(((Q4/1000)*6)*1000)-AVERAGE(R$47:R$49) -> 29.063958 | S4: =R4/(M4/1000) -> 140.2024 | T4: =(AA$13*(O4+0.1))+AA$14 -> 18.84745 | U4: =(((T4/1000)*6)*1000)-AVERAGE(U$47:U$49) -> 44.363 | V4: =U4/(M4/1000) -> 214.00386 | W4: =(AA$22*P4)+AA$23 -> 11.7444 | X4: =(((W4/1000)*6)*1000)-AVERAGE(X$47:X$49) -> 68.41125 | Y4: =X4/(M4/1000) -> 330.01085 | AA4: 98.857 | AB4: 10 | AC4: 0.089
A5: 18 | B5: Hoop | C5: native | D5: J_direct | E5: B | F5: 43661 | G5: 18 | H5: Hoop | I5: native | J5: J_direct | K5: B | L5: 1 | M5: 29.4 | N5: 0.078 | O5: 0.102 | P5: 0.138 | Q5: =(AA$4*N5)+AA$5 -> 8.380546 | R5: =(((Q5/1000)*6)*1000)-AVERAGE(R$47:R$49) -> 45.078792 | S5: =R5/(M5/1000) -> 1533.2922 | T5: =(AA$13*(O5+0.1))+AA$14 -> 20.1702 | U5: =(((T5/1000)*6)*1000)-AVERAGE(U$47:U$49) -> 52.2995 | V5: =U5/(M5/1000) -> 1778.8946 | W5: =(AA$22*P5)+AA$23 -> 13.7714 | X5: =(((W5/1000)*6)*1000)-AVERAGE(X$47:X$49) -> 80.57325 | Y5: =X5/(M5/1000) -> 2740.5867 | AA5: 0.6697 | AB5: 15 | AC5: 0.141
F6: 43661 | G6: 18 | H6: Hoop | I6: native | J6: J_direct | K6: B | L6: 2 | M6: 196.5 | N6: 0.077 | O6: 0.132 | P6: 0.175 | Q6: =(AA$4*N6)+AA$5 -> 8.281689 | R6: =(((Q6/1000)*6)*1000)-AVERAGE(R$47:R$49) -> 44.48565 | S6: =R6/(M6/1000) -> 226.39008 | T6: =(AA$13*(O6+0.1))+AA$14 -> 23.2227 | U6: =(((T6/1000)*6)*1000)-AVERAGE(U$47:U$49) -> 70.6145 | V6: =U6/(M6/1000) -> 359.36132 | W6: =(AA$22*P6)+AA$23 -> 17.52135 | X6: =(((W6/1000)*6)*1000)-AVERAGE(X$47:X$49) -> 103.07295 | Y6: =X6/(M6/1000) -> 524.54427 | AB6: 20 | AC6: 0.192
F7: 43661 | G7: 18 | H7: Hoop | I7: native | J7: J_direct | K7: B | L7: 3 | M7: 194.8 | N7: 0.082 | O7: 0.09 | P7: 0.114 | Q7: =(AA$4*N7)+AA$5 -> 8.775974 | R7: =(((Q7/1000)*6)*1000)-AVERAGE(R$47:R$49) -> 47.45136 | S7: =R7/(M7/1000) -> 243.59014 | T7: =(AA$13*(O7+0.1))+AA$14 -> 18.9492 | U7: =(((T7/1000)*6)*1000)-AVERAGE(U$47:U$49) -> 44.9735 | V7: =U7/(M7/1000) -> 230.87012 | W7: =(AA$22*P7)+AA$23 -> 11.339 | X7: =(((W7/1000)*6)*1000)-AVERAGE(X$47:X$49) -> 65.97885 | Y7: =X7/(M7/1000) -> 338.70046 | AB7: 30 | AC7: 0.31
A8: 30 | B8: Hoop | C8: native | D8: J_direct | E8: B | F8: 43661 | G8: 30 | H8: Hoop | I8: native | J8: J_direct | K8: B | L8: 1 | M8: 204 | N8: 0.066 | O8: 0.08 | P8: 0.118 | Q8: =(AA$4*N8)+AA$5 -> 7.194262 | R8: =(((Q8/1000)*6)*1000)-AVERAGE(R$47:R$49) -> 37.961088 | S8: =R8/(M8/1000) -> 186.08376 | T8: =(AA$13*(O8+0.1))+AA$14 -> 17.9317 | U8: =(((T8/1000)*6)*1000)-AVERAGE(U$47:U$49) -> 38.8685 | V8: =U8/(M8/1000) -> 190.53186 | W8: =(AA$22*P8)+AA$23 -> 11.7444 | X8: =(((W8/1000)*6)*1000)-AVERAGE(X$47:X$49) -> 68.41125 | Y8: =X8/(M8/1000) -> 335.34926 | AB8: 45 | AC8: 0.442
F9: 43661 | G9: 30 | H9: Hoop | I9: native | J9: J_direct | K9: B | L9: 2 | M9: 277 | N9: 0.089 | O9: 0.123 | P9: 0.211 | Q9: =(AA$4*N9)+AA$5 -> 9.467973 | R9: =(((Q9/1000)*6)*1000)-AVERAGE(R$47:R$49) -> 51.603354 | S9: =R9/(M9/1000) -> 186.2937 | T9: =(AA$13*(O9+0.1))+AA$14 -> 22.30695 | U9: =(((T9/1000)*6)*1000)-AVERAGE(U$47:U$49) -> 65.12 | V9: =U9/(M9/1000) -> 235.09025 | W9: =(AA$22*P9)+AA$23 -> 21.16995 | X9: =(((W9/1000)*6)*1000)-AVERAGE(X$47:X$49) -> 124.96455 | Y9: =X9/(M9/1000) -> 451.13556 | AB9: 60 | AC9: 0.604
F10: 43661 | G10: 30 | H10: Hoop | I10: native | J10: J_direct | K10: B | L10: 3 | M10: 219.3 | N10: 0.089 | O10: 0.143 | P10: 0.141 | Q10: =(AA$4*N10)+AA$5 -> 9.467973 | R10: =(((Q10/1000)*6)*1000)-AVERAGE(R$47:R$49) -> 51.603354 | S10: =R10/(M10/1000) -> 235.30941 | T10: =(AA$13*(O10+0.1))+AA$14 -> 24.34195 | U10: =(((T10/1000)*6)*1000)-AVERAGE(U$47:U$49) -> 77.33 | V10: =U10/(M10/1000) -> 352.62198 | W10: =(AA$22*P10)+AA$23 -> 14.07545 | X10: =(((W10/1000)*6)*1000)-AVERAGE(X$47:X$49) -> 82.39755 | Y10: =X10/(M10/1000) -> 375.72982 | AB10: 100 | AC10: 1.003
A11: 32 | B11: Hoop | C11: native | D11: J_direct | E11: B | F11: 43661 | G11: 32 | H11: Hoop | I11: native | J11: J_direct | K11: B | L11: 1 | M11: 206.5 | N11: 0.039 | O11: 0.129 | P11: 0.084 | Q11: =(AA$4*N11)+AA$5 -> 4.525123 | R11: =(((Q11/1000)*6)*1000)-AVERAGE(R$47:R$49) -> 21.946254 | S11: =R11/(M11/1000) -> 106.27726 | T11: =(AA$13*(O11+0.1))+AA$14 -> 22.91745 | U11: =(((T11/1000)*6)*1000)-AVERAGE(U$47:U$49) -> 68.783 | V11: =U11/(M11/1000) -> 333.08959 | W11: =(AA$22*P11)+AA$23 -> 8.2985 | X11: =(((W11/1000)*6)*1000)-AVERAGE(X$47:X$49) -> 47.73585 | Y11: =X11/(M11/1000) -> 231.16634 | AA11: 43662 | AB11: 0 | AC11: 0.002
F12: 43661 | G12: 32 | H12: Hoop | I12: native | J12: J_direct | K12: B | L12: 2 | M12: 202.9 | N12: 0.043 | O12: 0.088 | P12: 0.116 | Q12: =(AA$4*N12)+AA$5 -> 4.920551 | R12: =(((Q12/1000)*6)*1000)-AVERAGE(R$47:R$49) -> 24.318822 | S12: =R12/(M12/1000) -> 119.8562 | T12: =(AA$13*(O12+0.1))+AA$14 -> 18.7457 | U12: =(((T12/1000)*6)*1000)-AVERAGE(U$47:U$49) -> 43.7525 | V12: =U12/(M12/1000) -> 215.63578 | W12: =(AA$22*P12)+AA$23 -> 11.5417 | X12: =(((W12/1000)*6)*1000)-AVERAGE(X$47:X$49) -> 67.19505 | Y12: =X12/(M12/1000) -> 331.17324 | AB12: 5 | AC12: 0.05
F13: 43661 | G13: 32 | H13: Hoop | I13: native | J13: J_direct | K13: B | L13: 3 | M13: 211.5 | N13: 0.053 | O13: 0.1 | P13: 0.122 | Q13: =(AA$4*N13)+AA$5 -> 5.909121 | R13: =(((Q13/1000)*6)*1000)-AVERAGE(R$47:R$49) -> 30.250242 | S13: =R13/(M13/1000) -> 143.02715 | T13: =(AA$13*(O13+0.1))+AA$14 -> 19.9667 | U13: =(((T13/1000)*6)*1000)-AVERAGE(U$47:U$49) -> 51.0785 | V13: =U13/(M13/1000) -> 241.50591 | W13: =(AA$22*P13)+AA$23 -> 12.1498 | X13: =(((W13/1000)*6)*1000)-AVERAGE(X$47:X$49) -> 70.84365 | Y13: =X13/(M13/1000) -> 334.95816 | AA13: 101.75 | AB13: 10 | AC13: 0.098
A14: 33 | B14: Hoop | C14: native | D14: J_direct | E14: B | F14: 43661 | G14: 33 | H14: Hoop | I14: native | J14: J_direct | K14: B | L14: 1 | M14: 231.1 | N14: 0.068 | O14: 0.093 | P14: 0.138 | Q14: =(AA$4*N14)+AA$5 -> 7.391976 | R14: =(((Q14/1000)*6)*1000)-AVERAGE(R$47:R$49) -> 39.147372 | S14: =R14/(M14/1000) -> 169.39581 | T14: =(AA$13*(O14+0.1))+AA$14 -> 19.25445 | U14: =(((T14/1000)*6)*1000)-AVERAGE(U$47:U$49) -> 46.805 | V14: =U14/(M14/1000) -> 202.53137 | W14: =(AA$22*P14)+AA$23 -> 13.7714 | X14: =(((W14/1000)*6)*1000)-AVERAGE(X$47:X$49) -> 80.57325 | Y14: =X14/(M14/1000) -> 348.65102 | AA14: -0.3833 | AB14: 15 | AC14: 0.145
F15: 43661 | G15: 33 | H15: Hoop | I15: native | J15: J_direct | K15: B | L15: 2 | M15: 227.9 | N15: 0.075 | O15: 0.094 | P15: 0.146 | Q15: =(AA$4*N15)+AA$5 -> 8.083975 | R15: =(((Q15/1000)*6)*1000)-AVERAGE(R$47:R$49) -> 43.299366 | S15: =R15/(M15/1000) -> 189.99283 | T15: =(AA$13*(O15+0.1))+AA$14 -> 19.3562 | U15: =(((T15/1000)*6)*1000)-AVERAGE(U$47:U$49) -> 47.4155 | V15: =U15/(M15/1000) -> 208.05397 | W15: =(AA$22*P15)+AA$23 -> 14.5822 | X15: =(((W15/1000)*6)*1000)-AVERAGE(X$47:X$49) -> 85.43805 | Y15: =X15/(M15/1000) -> 374.89272 | AB15: 20 | AC15: 0.191
F16: 43661 | G16: 33 | H16: Hoop | I16: native | J16: J_direct | K16: B | L16: 3 | M16: 202.9 | N16: 0.082 | O16: 0.09 | P16: 0.134 | Q16: =(AA$4*N16)+AA$5 -> 8.775974 | R16: =(((Q16/1000)*6)*1000)-AVERAGE(R$47:R$49) -> 47.45136 | S16: =R16/(M16/1000) -> 233.86575 | T16: =(AA$13*(O16+0.1))+AA$14 -> 18.9492 | U16: =(((T16/1000)*6)*1000)-AVERAGE(U$47:U$49) -> 44.9735 | V16: =U16/(M16/1000) -> 221.65352 | W16: =(AA$22*P16)+AA$23 -> 13.366 | X16: =(((W16/1000)*6)*1000)-AVERAGE(X$47:X$49) -> 78.14085 | Y16: =X16/(M16/1000) -> 385.12001 | AB16: 30 | AC16: 0.296
A17: 43 | B17: Quesadilla | C17: native | D17: J_direct | E17: B | F17: 43661 | G17: 43 | H17: Quesadilla | I17: native | J17: J_direct | K17: B | L17: 1 | M17: 212.2 | N17: 0.125 | O17: 0.14 | P17: 0.15 | Q17: =(AA$4*N17)+AA$5 -> 13.026825 | R17: =(((Q17/1000)*6)*1000)-AVERAGE(R$47:R$49) -> 72.956466 | S17: =R17/(M17/1000) -> 343.80992 | T17: =(AA$13*(O17+0.1))+AA$14 -> 24.0367 | U17: =(((T17/1000)*6)*1000)-AVERAGE(U$47:U$49) -> 75.4985 | V17: =U17/(M17/1000) -> 355.78935 | W17: =(AA$22*P17)+AA$23 -> 14.9876 | X17: =(((W17/1000)*6)*1000)-AVERAGE(X$47:X$49) -> 87.87045 | Y17: =X17/(M17/1000) -> 414.0926 | AB17: 45 | AC17: 0.453
F18: 43661 | G18: 43 | H18: Quesadilla | I18: native | J18: J_direct | K18: B | L18: 2 | M18: 206.2 | N18: 0.122 | O18: 0.133 | P18: 0.154 | Q18: =(AA$4*N18)+AA$5 -> 12.730254 | R18: =(((Q18/1000)*6)*1000)-AVERAGE(R$47:R$49) -> 71.17704 | S18: =R18/(M18/1000) -> 345.18448 | T18: =(AA$13*(O18+0.1))+AA$14 -> 23.32445 | U18: =(((T18/1000)*6)*1000)-AVERAGE(U$47:U$49) -> 71.225 | V18: =U18/(M18/1000) -> 345.41707 | W18: =(AA$22*P18)+AA$23 -> 15.393 | X18: =(((W18/1000)*6)*1000)-AVERAGE(X$47:X$49) -> 90.30285 | Y18: =X18/(M18/1000) -> 437.93817 | AB18: 60 | AC18: 0.597
F19: 43661 | G19: 43 | H19: Quesadilla | I19: native | J19: J_direct | K19: B | L19: 3 | M19: 215.8 | N19: 0.118 | O19: 0.107 | P19: 0.166 | Q19: =(AA$4*N19)+AA$5 -> 12.334826 | R19: =(((Q19/1000)*6)*1000)-AVERAGE(R$47:R$49) -> 68.804472 | S19: =R19/(M19/1000) -> 318.83444 | T19: =(AA$13*(O19+0.1))+AA$14 -> 20.67895 | U19: =(((T19/1000)*6)*1000)-AVERAGE(U$47:U$49) -> 55.352 | V19: =U19/(M19/1000) -> 256.49676 | W19: =(AA$22*P19)+AA$23 -> 16.6092 | X19: =(((W19/1000)*6)*1000)-AVERAGE(X$47:X$49) -> 97.60005 | Y19: =X19/(M19/1000) -> 452.27085 | AB19: 100 | AC19: 0.985
A20: 50 | B20: Quesadilla | C20: native | D20: J_direct | E20: B | F20: 43661 | G20: 50 | H20: Quesadilla | I20: native | J20: J_direct | K20: B | L20: 1 | M20: 209 | N20: 0.117 | O20: 0.149 | P20: 0.22 | Q20: =(AA$4*N20)+AA$5 -> 12.235969 | R20: =(((Q20/1000)*6)*1000)-AVERAGE(R$47:R$49) -> 68.21133 | S20: =R20/(M20/1000) -> 326.37 | T20: =(AA$13*(O20+0.1))+AA$14 -> 24.95245 | U20: =(((T20/1000)*6)*1000)-AVERAGE(U$47:U$49) -> 80.993 | V20: =U20/(M20/1000) -> 387.52632 | W20: =(AA$22*P20)+AA$23 -> 22.0821 | X20: =(((W20/1000)*6)*1000)-AVERAGE(X$47:X$49) -> 130.43745 | Y20: =X20/(M20/1000) -> 624.10263 | AA20: 43663 | AB20: 0 | AC20: 0.003
F21: 43661 | G21: 50 | H21: Quesadilla | I21: native | J21: J_direct | K21: B | L21: 2 | M21: 216.6 | N21: 0.152 | O21: 0.199 | P21: 0.22 | Q21: =(AA$4*N21)+AA$5 -> 15.695964 | R21: =(((Q21/1000)*6)*1000)-AVERAGE(R$47:R$49) -> 88.9713 | S21: =R21/(M21/1000) -> 410.76316 | T21: =(AA$13*(O21+0.1))+AA$14 -> 30.03995 | U21: =(((T21/1000)*6)*1000)-AVERAGE(U$47:U$49) -> 111.518 | V21: =U21/(M21/1000) -> 514.85688 | W21: =(AA$22*P21)+AA$23 -> 22.0821 | X21: =(((W21/1000)*6)*1000)-AVERAGE(X$47:X$49) -> 130.43745 | Y21: =X21/(M21/1000) -> 602.20429 | AB21: 5 | AC21: 0.053
F22: 43661 | G22: 50 | H22: Quesadilla | I22: native | J22: J_direct | K22: B | L22: 3 | M22: 226 | N22: 0.144 | O22: 0.192 | P22: 0.219 | Q22: =(AA$4*N22)+AA$5 -> 14.905108 | R22: =(((Q22/1000)*6)*1000)-AVERAGE(R$47:R$49) -> 84.226164 | S22: =R22/(M22/1000) -> 372.68214 | T22: =(AA$13*(O22+0.1))+AA$14 -> 29.3277 | U22: =(((T22/1000)*6)*1000)-AVERAGE(U$47:U$49) -> 107.2445 | V22: =U22/(M22/1000) -> 474.53319 | W22: =(AA$22*P22)+AA$23 -> 21.98075 | X22: =(((W22/1000)*6)*1000)-AVERAGE(X$47:X$49) -> 129.82935 | Y22: =X22/(M22/1000) -> 574.46615 | AA22: 101.35 | AB22: 10 | AC22: 0.099
F23: 43661 | G23: 51 | H23: Quesadilla | I23: native | J23: J_direct | K23: B | L23: 1 | M23: 201 | N23: 0.054 | O23: 0.093 | P23: 0.105 | Q23: =(AA$4*N23)+AA$5 -> 6.007978 | R23: =(((Q23/1000)*6)*1000)-AVERAGE(R$47:R$49) -> 30.843384 | S23: =R23/(M23/1000) -> 153.44967 | T23: =(AA$13*(O23+0.1))+AA$14 -> 19.25445 | U23: =(((T23/1000)*6)*1000)-AVERAGE(U$47:U$49) -> 46.805 | V23: =U23/(M23/1000) -> 232.8607 | W23: =(AA$22*P23)+AA$23 -> 10.42685 | X23: =(((W23/1000)*6)*1000)-AVERAGE(X$47:X$49) -> 60.50595 | Y23: =X23/(M23/1000) -> 301.02463 | AA23: -0.2149 | AB23: 15 | AC23: 0.149
F24: 43661 | G24: 51 | H24: Quesadilla | I24: native | J24: J_direct | K24: B | L24: 2 | M24: 213.6 | N24: 0.064 | O24: 0.088 | P24: 0.137 | Q24: =(AA$4*N24)+AA$5 -> 6.996548 | R24: =(((Q24/1000)*6)*1000)-AVERAGE(R$47:R$49) -> 36.774804 | S24: =R24/(M24/1000) -> 172.16669 | T24: =(AA$13*(O24+0.1))+AA$14 -> 18.7457 | U24: =(((T24/1000)*6)*1000)-AVERAGE(U$47:U$49) -> 43.7525 | V24: =U24/(M24/1000) -> 204.8338 | W24: =(AA$22*P24)+AA$23 -> 13.67005 | X24: =(((W24/1000)*6)*1000)-AVERAGE(X$47:X$49) -> 79.96515 | Y24: =X24/(M24/1000) -> 374.36868 | AB24: 20 | AC24: 0.187
F25: 43661 | G25: 51 | H25: Quesadilla | I25: native | J25: J_direct | K25: B | L25: 3 | M25: 212.8 | N25: 0.059 | O25: 0.1 | P25: 0.12 | Q25: =(AA$4*N25)+AA$5 -> 6.502263 | R25: =(((Q25/1000)*6)*1000)-AVERAGE(R$47:R$49) -> 33.809094 | S25: =R25/(M25/1000) -> 158.87732 | T25: =(AA$13*(O25+0.1))+AA$14 -> 19.9667 | U25: =(((T25/1000)*6)*1000)-AVERAGE(U$47:U$49) -> 51.0785 | V25: =U25/(M25/1000) -> 240.03055 | W25: =(AA$22*P25)+AA$23 -> 11.9471 | X25: =(((W25/1000)*6)*1000)-AVERAGE(X$47:X$49) -> 69.62745 | Y25: =X25/(M25/1000) -> 327.19666 | AB25: 30 | AC25: 0.3
